<?xml version="1.0"?>

<robot name="balancing_robot">

  <!-- publish to topic /imu -->
  <gazebo>
    <plugin
      filename="gz-sim-imu-system"
      name="gz::sim::systems::Imu">
    </plugin>
  </gazebo>

  <!-- subcribe to topic /cmd_vel -->
  <gazebo>  
    <plugin
      filename="gz-sim-diff-drive-system"
      name="gz::sim::systems::DiffDrive">
      <left_joint>left_wheel_joint</left_joint>
      <right_joint>right_wheel_joint</right_joint>
      <wheel_separation>0.28</wheel_separation>
      <wheel_radius>0.04</wheel_radius>
      <odom_publish_frequency>50</odom_publish_frequency>
      <topic>cmd_vel</topic>
    </plugin>
  </gazebo>

  <link name="base_footprint">
    <inertial>
      <mass value="0.001"/>
      <inertia ixx="0.0001" ixy="0" ixz="0" iyy="0.0001" iyz="0" izz="0.0001"/>
    </inertial>
  </link>
  
  <joint name="base_footprint_joint" type="fixed">
    <parent link="base_footprint" />
    <child link="base_link" />
    <!-- Change rpy from "0 0 0" to "0 0.035 0" (approx 2 degrees forward) -->
    <origin xyz="0 0 0" rpy="0 0.035 0" /> 
  </joint>


  <link name="base_link">
    <visual>
      <origin xyz="0 0 0.11" rpy="0 0 0"/> 
      <geometry><box size="0.08 0.19 0.12"/></geometry>
      <material name="green">
        <color rgba="0 1 0 1" />
      </material>
    </visual>
    <collision>
      <origin xyz="0 0 0.11" rpy="0 0 0"/>
      <geometry><box size="0.08 0.19 0.12"/></geometry>
    </collision>
    <inertial>
      <origin xyz="0 0 0.11" rpy="0 0 0"/> 
      <mass value="0.89"/>
      <inertia ixx="0.00374" ixy="0" ixz="0" iyy="0.00154" iyz="0" izz="0.00315"/>
    </inertial>
  </link>

  <link name="right_wheel">
    <visual>
      <geometry>
        <cylinder radius="0.04" length="0.04" />
      </geometry>
      <material name="black">
        <color rgba="0 0 0 1" />
      </material>
    </visual>

    <collision>
      <geometry>
        <cylinder radius="0.04" length="0.04" />
      </geometry>
    </collision>

    <inertial>
      <mass value="0.2"/>
      <inertia ixx="0.00015" ixy="0" ixz="0" iyy="0.00015" iyz="0" izz="0.00025"/>
    </inertial>
  </link>

  <link name="left_wheel">
    <visual>
      <geometry>
        <cylinder radius="0.04" length="0.04" />
      </geometry>
      <material name="black">
        <color rgba="0 0 0 1" />
      </material>
    </visual>

    <collision>
      <geometry>
        <cylinder radius="0.04" length="0.04" />
      </geometry>
    </collision>

    <inertial>
      <mass value="0.2"/>
      <inertia ixx="0.00015" ixy="0" ixz="0" iyy="0.00015" iyz="0" izz="0.00025"/>
    </inertial>
  </link>

  <joint name="right_wheel_joint" type="continuous">
    <parent link="base_link" />
    <child link="right_wheel" />
    <origin xyz="0 -0.14 0" rpy="-1.5708 0 0" /> 
    <axis xyz="0 0 1" />
  </joint>

  <joint name="left_wheel_joint" type="continuous">
    <parent link="base_link" />
    <child link="left_wheel" />
    <origin xyz="0 0.14 0" rpy="-1.5708 0 0" />
    <axis xyz="0 0 1" />
  </joint>

  <gazebo reference="base_link">
    <mu1>0.2</mu1>
    <mu2>0.2</mu2>
    <self_collide>false</self_collide>
  </gazebo>

  <gazebo reference="left_wheel">
    <mu1>1.0</mu1>
    <mu2>1.0</mu2>
  </gazebo>

  <gazebo reference="right_wheel">
    <mu1>1.0</mu1>
    <mu2>1.0</mu2>
  </gazebo>


  <gazebo reference="base_link">
    <sensor name="imu_sensor" type="imu">
      <always_on>true</always_on>
      <update_rate>100</update_rate>
      <visualize>true</visualize>
      <topic>imu</topic>
      <imu></imu>
    </sensor>
  </gazebo>

</robot>